Workbook

Sheet Dashboard
B2: 3879 Rendon Rd — Multi-Tenant IOS DCF
B3: ANNUAL DISCOUNTED CASH FLOW | SELLER OWNS FREE AND CLEAR | LIVE FROM THE INPUTS, RENTROLL AND CAPEX TABS
B4: SCENARIO | D4: Base | F4: HOLD (YEARS) | H4: =Hold -> 7 | I4: EXIT CAP | K4: =ExitCap -> 0.07 | L4: RENT GROWTH | M4: =RentGrowth -> 0.03
B6: KEY METRICS
B7: PURCHASE PRICE (INPUT) | E7: GOING-IN CAP RATE | H7: UNLEVERED IRR | K7: LEVERED IRR
B8: =PurchPrice -> 5500000 | E8: =CashFlow!$C$70 -> 0.077784545 | H8: =CashFlow!$C$66 -> 0.10529541 | K8: =CashFlow!$C$68 -> 0.13893901
B9: =TEXT(PurchPrice/Acres,"$#,##0")&" per acre, placeholder" -> $148,649 per acre, placeholder | E9: ="Year-1 NOI "&TEXT(CashFlow!$C$78,"$#,##0") -> Year-1 NOI $427,815 | H9: ="Equity multiple "&TEXT(CashFlow!$C$67,"0.00")&"x" -> Equity multiple 1.82x | K9: ="Equity multiple "&TEXT(CashFlow!$C$69,"0.00")&"x" -> Equity multiple 2.23x
B11: YEAR-1 NOI | E11: YIELD ON COST | H11: AVG CASH-ON-CASH | K11: MIN DSCR
B12: =CashFlow!$C$78 -> 427815 | E12: =CashFlow!$C$71 -> 0.079069547 | H12: =CashFlow!$C$73 -> 0.079849921 | K12: =IF(LevOn=0,"n/a",CashFlow!$C$74) -> 1.830173
B13: ="Scenario revenue "&TEXT(CashFlow!$D$19,"$#,##0") -> Scenario revenue $457,700 | E13: ="Year-2 NOI on total cost incl. capex" -> Year-2 NOI on total cost incl. capex | H13: ="Equity "&TEXT(CashFlow!$C$72,"$#,##0") -> Equity $2,587,750 | K13: ="Loan "&TEXT(CashFlow!$C$79,"$#,##0")&" at "&TEXT(LoanLTV,"0%")&" LTV" -> Loan $3,025,000 at 55% LTV
B15: GROSS EXIT VALUE | E15: SOLVED MAX PRICE | H15: POTENTIAL BASE REVENUE | K15: INPUT PRICE VS SOLVED
B16: =CashFlow!$C$75 -> 7211101.9 | E16: =CashFlow!$C$80 -> 5656335.3 | H16: =RentRoll!$H$17 -> 711200 | K16: =CashFlow!$C$82 -> -0.027638975
B17: ="Exit cap "&TEXT(ExitCap,"0.00%")&" on forward NOI" -> Exit cap 7.00% on forward NOI | E17: =TEXT(CashFlow!$C$81,"$#,##0")&" per acre at "&TEXT(TgtUnlev,"0.0%")&" unlevered" -> $152,874 per acre at 10.0% unlevered | H17: ="In this scenario: "&TEXT(RentRoll!$H$20,"$#,##0")&" per year" -> In this scenario: $471,200 per year | K17: ="Positive = paying above the target-IRR price" -> Positive = paying above the target-IRR price
B19: RISK FLAGS | H19: POTENTIAL BASE REVENUE — EVERY TENANT
B20: Flag | E20: Metric | F20: Threshold | G20: Status | H20: Tenant | K20: Potential $/yr | L20: In scenario | M20: Scenario $/yr
B21: Unlevered IRR vs target | E21: =CashFlow!$C$66 -> 0.10529541 | F21: ="≥ "&TEXT(TgtUnlev,"0.0%") -> ≥ 10.0% | G21: =IF(NOT(ISNUMBER(E21)),"FLAG",IF(E21>=TgtUnlev,"PASS",IF(E21>=TgtUnlev-0.02,"WATCH","FLAG"))) -> PASS | H21: =RentRoll!B6&IF(RentRoll!C6="Pipeline"," (pipeline)","") -> S&A Leasing | K21: =RentRoll!H6 -> 156000 | L21: =RentRoll!P6 -> 1 | M21: =K21*L21 -> 156000
B22: Levered IRR vs target | E22: =CashFlow!$C$68 -> 0.13893901 | F22: ="≥ "&TEXT(TgtLev,"0.0%") -> ≥ 15.0% | G22: =IF(LevOn=0,"N/A",IF(NOT(ISNUMBER(E22)),"FLAG",IF(E22>=TgtLev,"PASS",IF(E22>=TgtLev-0.03,"WATCH","FLAG")))) -> WATCH | H22: =RentRoll!B7&IF(RentRoll!C7="Pipeline"," (pipeline)","") -> Reindeer (Prime) | K22: =RentRoll!H7 -> 84000 | L22: =RentRoll!P7 -> 1 | M22: =K22*L22 -> 84000
B23: Minimum DSCR vs covenant | E23: =IF(LevOn=0,"n/a",CashFlow!$C$74) -> 1.830173 | F23: ="≥ "&TEXT(MinDSCR,"0.00")&"x" -> ≥ 1.25x | G23: =IF(LevOn=0,"N/A",IF(E23>=MinDSCR,"PASS",IF(E23>=MinDSCR-0.15,"WATCH","FLAG"))) -> PASS | H23: =RentRoll!B8&IF(RentRoll!C8="Pipeline"," (pipeline)","") -> Straight 6 | K23: =RentRoll!H8 -> 78000 | L23: =RentRoll!P8 -> 1 | M23: =K23*L23 -> 78000
B24: Input price vs solved max price | E24: =CashFlow!$C$82 -> -0.027638975 | F24: ="≤ 0%" -> ≤ 0% | G24: =IF(E24<=0,"PASS",IF(E24<=0.05,"WATCH","FLAG")) -> PASS | H24: =RentRoll!B9&IF(RentRoll!C9="Pipeline"," (pipeline)","") -> Big Dawgs (repo) | K24: =RentRoll!H9 -> 48000 | L24: =RentRoll!P9 -> 1 | M24: =K24*L24 -> 48000
B25: Property tax if reassessed (Yr-1) | E25: =CashFlow!$C$83 -> 121000 | F25: ="vs seller "&TEXT(SellerTax,"$#,##0") -> vs seller $5,000 | G25: =IF(TaxSwitch=1,"PASS",IF(E25>2*SellerTax,"FLAG","WATCH")) -> FLAG | H25: =RentRoll!B10&IF(RentRoll!C10="Pipeline"," (pipeline)","") -> Individual tenants (various) | K25: =RentRoll!H10 -> 25200 | L25: =RentRoll!P10 -> 1 | M25: =K25*L25 -> 25200
B26: Mgmt fee and reserves underwritten | E26: =TEXT(MgmtPct,"0.0%")&" / $"&TEXT(ReservePerAcre,"#,##0")&" ac" -> 0.0% / $0 ac | F26: ="Both above 0" -> Both above 0 | G26: =IF(AND(MgmtPct>0,ReservePerAcre>0),"PASS","WATCH") -> WATCH | H26: =RentRoll!B11&IF(RentRoll!C11="Pipeline"," (pipeline)","") -> CDL driver training | K26: =RentRoll!H11 -> 18000 | L26: =RentRoll!P11 -> 1 | M26: =K26*L26 -> 18000
B27: Pipeline share of Year-2 revenue | E27: =IF(CashFlow!$E$19=0,0,SUMIF(RentRoll!$C$6:$C$15,"Pipeline",CashFlow!$E$9:$E$18)/CashFlow!$E$19) -> 0.11460102 | F27: ="≤ 15%" -> ≤ 15% | G27: =IF(E27<=0.15,"PASS",IF(E27<=0.3,"WATCH","FLAG")) -> PASS | H27: =RentRoll!B12&IF(RentRoll!C12="Pipeline"," (pipeline)","") -> Alamo Fireworks | K27: =RentRoll!H12 -> 8000 | L27: =RentRoll!P12 -> 1 | M27: =K27*L27 -> 8000
B28: Largest-tenant concentration (Yr-1) | E28: =IF(CashFlow!$D$19=0,0,MAX(CashFlow!$D$9:$D$18)/CashFlow!$D$19) -> 0.34083461 | F28: ="≤ 35%" -> ≤ 35% | G28: =IF(E28<=0.35,"PASS",IF(E28<=0.5,"WATCH","FLAG")) -> PASS | H28: =RentRoll!B13&IF(RentRoll!C13="Pipeline"," (pipeline)","") -> Prime expansion (+1 ac) (pipeline) | K28: =RentRoll!H13 -> 42000 | L28: =RentRoll!P13 -> 1 | M28: =K28*L28 -> 42000
B29: Lease expirations inside hold | E29: =SUMPRODUCT((RentRoll!$K$6:$K$15<>"")*(RentRoll!$K$6:$K$15<=Hold*12)*(RentRoll!$P$6:$P$15>0)) -> 2 | F29: ="0" -> 0 | G29: =IF(E29=0,"PASS","WATCH") -> WATCH | H29: =RentRoll!B14&IF(RentRoll!C14="Pipeline"," (pipeline)","") -> Straight 6 expansion (~10 spots) (pipeline) | K29: =RentRoll!H14 -> 12000 | L29: =RentRoll!P14 -> 1 | M29: =K29*L29 -> 12000
B30: Revenue with no stated lease term | E30: =IF(CashFlow!$D$19=0,0,SUMPRODUCT((RentRoll!$K$6:$K$15="")*CashFlow!$D$9:$D$18)/CashFlow!$D$19) -> 0.47563906 | F30: ="≤ 40%" -> ≤ 40% | G30: =IF(E30<=0.4,"PASS",IF(E30<=0.6,"WATCH","FLAG")) -> WATCH | H30: =RentRoll!B15&IF(RentRoll!C15="Pipeline"," (pipeline)","") -> Large tenant (~5.75 ac, in county) (pipeline) | K30: =RentRoll!H15 -> 240000 | L30: =RentRoll!P15 -> 0 | M30: =K30*L30 -> 0
B31: Pipeline, concentration and lease-term flags use the active scenario. IRR and DSCR thresholds are set on Inputs. | H31: POTENTIAL BASE REVENUE | K31: =SUM(K21:K30) -> 711200 | L31: =IF(K31=0,0,M31/K31) -> 0.66254218 | M31: =SUM(M21:M30) -> 471200
B33: SENSITIVITY — EXIT CAP (ACROSS) BY RENT GROWTH (DOWN)
B34: UNLEVERED IRR | H34: LEVERED IRR
B35: Growth / Cap | C35: =Sens!$B$79 -> 0.06 | D35: =Sens!$B$80 -> 0.065 | E35: =Sens!$B$81 -> 0.07 | F35: =Sens!$B$82 -> 0.075 | G35: =Sens!$B$83 -> 0.08 | H35: Growth / Cap | I35: =Sens!$B$79 -> 0.06 | J35: =Sens!$B$80 -> 0.065 | K35: =Sens!$B$81 -> 0.07 | L35: =Sens!$B$82 -> 0.075 | M35: =Sens!$B$83 -> 0.08
B36: =RentGrowth+Sens!$B$6 -> 0.01 | C36: =Sens!$O$79 -> 0.10978368 | D36: =Sens!$O$80 -> 0.10008869 | E36: =Sens!$O$81 -> 0.091310546 | F36: =Sens!$O$82 -> 0.083310305 | G36: =Sens!$O$83 -> 0.075977423 | H36: =RentGrowth+Sens!$B$6 -> 0.01 | I36: =Sens!$O$106 -> 0.1464868 | J36: =Sens!$O$107 -> 0.12942379 | K36: =Sens!$O$108 -> 0.11334639 | L36: =Sens!$O$109 -> 0.098082644 | M36: =Sens!$O$110 -> 0.083492333
B37: =RentGrowth+Sens!$B$20 -> 0.02 | C37: =Sens!$O$84 -> 0.11687184 | D37: =Sens!$O$85 -> 0.10709699 | E37: =Sens!$O$86 -> 0.098245891 | F37: =Sens!$O$87 -> 0.090178583 | G37: =Sens!$O$88 -> 0.082783714 | H37: =RentGrowth+Sens!$B$20 -> 0.02 | I37: =Sens!$O$111 -> 0.15871642 | J37: =Sens!$O$112 -> 0.14196065 | K37: =Sens!$O$113 -> 0.12621806 | L37: =Sens!$O$114 -> 0.11131818 | M37: =Sens!$O$115 -> 0.097122863
B38: =RentGrowth+Sens!$B$34 -> 0.03 | C38: =Sens!$O$89 -> 0.12407765 | D38: =Sens!$O$90 -> 0.11422113 | E38: =Sens!$O$91 -> 0.10529541 | F38: =Sens!$O$92 -> 0.097159482 | G38: =Sens!$O$93 -> 0.089701181 | H38: =RentGrowth+Sens!$B$34 -> 0.03 | I38: =Sens!$O$116 -> 0.17086695 | J38: =Sens!$O$117 -> 0.15438454 | K38: =Sens!$O$118 -> 0.13893901 | L38: =Sens!$O$119 -> 0.12436077 | M38: =Sens!$O$120 -> 0.11051297
B39: =RentGrowth+Sens!$B$48 -> 0.04 | C39: =Sens!$O$94 -> 0.13139678 | D39: =Sens!$O$95 -> 0.12145687 | E39: =Sens!$O$96 -> 0.11245493 | F39: =Sens!$O$97 -> 0.1042489 | G39: =Sens!$O$98 -> 0.096725791 | H39: =RentGrowth+Sens!$B$48 -> 0.04 | I39: =Sens!$O$121 -> 0.18294457 | J39: =Sens!$O$122 -> 0.16670501 | K39: =Sens!$O$123 -> 0.15152294 | L39: =Sens!$O$124 -> 0.13722917 | M39: =Sens!$O$125 -> 0.12368759
B40: =RentGrowth+Sens!$B$62 -> 0.05 | C40: =Sens!$O$99 -> 0.13882495 | D40: =Sens!$O$100 -> 0.1288 | E40: =Sens!$O$101 -> 0.11972031 | F40: =Sens!$O$102 -> 0.11144277 | G40: =Sens!$O$103 -> 0.10385353 | H40: =RentGrowth+Sens!$B$62 -> 0.05 | I40: =Sens!$O$126 -> 0.19495487 | J40: =Sens!$O$127 -> 0.17893062 | K40: =Sens!$O$128 -> 0.16398198 | L40: =Sens!$O$129 -> 0.14993978 | M40: =Sens!$O$130 -> 0.13666826
B42: ANNUAL CASH FLOW SUMMARY (HOLD PERIOD)
B43: $ | D43: ="Yr "&CashFlow!D$4 -> Yr 1 | E43: ="Yr "&CashFlow!E$4 -> Yr 2 | F43: ="Yr "&CashFlow!F$4 -> Yr 3 | G43: ="Yr "&CashFlow!G$4 -> Yr 4 | H43: ="Yr "&CashFlow!H$4 -> Yr 5 | I43: ="Yr "&CashFlow!I$4 -> Yr 6 | J43: ="Yr "&CashFlow!J$4 -> Yr 7 | K43: ="Yr "&CashFlow!K$4 -> Yr 8 | ... M43: ="Yr "&CashFlow!M$4 -> Yr 10
B44: Effective gross revenue | D44: =CashFlow!D21*CashFlow!D$5 -> 434815 | E44: =CashFlow!E21*CashFlow!E$5 -> 461069.2 | F44: =CashFlow!F21*CashFlow!F$5 -> 466435.29 | G44: =CashFlow!G21*CashFlow!G$5 -> 480428.35 | H44: =CashFlow!H21*CashFlow!H$5 -> 494841.2 | I44: =CashFlow!I21*CashFlow!I$5 -> 483915.78 | J44: =CashFlow!J21*CashFlow!J$5 -> 498433.25 | K44: =CashFlow!K21*CashFlow!K$5 -> 0 | ... M44: =CashFlow!M21*CashFlow!M$5 -> 0
B45: NOI | D45: =CashFlow!D40 -> 427815 | E45: =CashFlow!E40 -> 453859.2 | F45: =CashFlow!F40 -> 459008.99 | G45: =CashFlow!G40 -> 472779.26 | H45: =CashFlow!H40 -> 486962.64 | I45: =CashFlow!I40 -> 475800.86 | J45: =CashFlow!J40 -> 490074.88 | K45: =CashFlow!K40 -> 0 | ... M45: =CashFlow!M40 -> 0
B46: Capex and reserves | D46: =CashFlow!D41 -> -112500 | E46: =CashFlow!E41 -> -45000 | F46: =CashFlow!F41 -> 0 | G46: =CashFlow!G41 -> 0 | H46: =CashFlow!H41 -> 0 | I46: =CashFlow!I41 -> 0 | J46: =CashFlow!J41 -> 0 | K46: =CashFlow!K41 -> 0 | ... M46: =CashFlow!M41 -> 0
B47: Debt service | D47: =CashFlow!D53*CashFlow!D$5 -> -204187.5 | E47: =CashFlow!E53*CashFlow!E$5 -> -204187.5 | F47: =CashFlow!F53*CashFlow!F$5 -> -250800.88 | G47: =CashFlow!G53*CashFlow!G$5 -> -250800.88 | H47: =CashFlow!H53*CashFlow!H$5 -> -250800.88 | I47: =CashFlow!I53*CashFlow!I$5 -> -250800.88 | J47: =CashFlow!J53*CashFlow!J$5 -> -250800.88 | K47: =CashFlow!K53*CashFlow!K$5 -> 0 | ... M47: =CashFlow!M53*CashFlow!M$5 -> 0
...

Sheet Inputs
A1: Inputs and Assumptions — 3879 Rendon Rd
A2: Blue text = input you can change · Dotted underline = placeholder or assumption to confirm · Black = formula · Green = link from another tab. Rent data is from Kenny's email; everything else is noted.
A4: SCENARIO LEVERS | B4: Base | C4: Upside | D4: Downside | E4: Active | F4: Notes
A5: Market rent growth (annual) | B5: 0.03 | C5: 0.04 | D5: 0.015 | E5: =INDEX($B5:$D5,ScenIdx) -> 0.03 | F5: ASSUMPTION. Applies to tenants with no stated bump (RentRoll col I blank). S&A uses its own bump.
A6: Vacancy & credit loss (% of revenue) | B6: 0.05 | C6: 0.03 | D6: 0.1 | E6: =INDEX($B6:$D6,ScenIdx) -> 0.05 | F6: ASSUMPTION. Applied on top of tenant timing; several tenants are month-to-month or vary monthly.
A7: Exit cap rate (on forward NOI) | B7: 0.07 | C7: 0.065 | D7: 0.0775 | E7: =INDEX($B7:$D7,ScenIdx) -> 0.07 | F7: ASSUMPTION. Replace with current small-bay IOS cap rate comps.
A8: Capex cost overrun | B8: 0 | C8: 0 | D8: 0.15 | E8: =INDEX($B8:$D8,ScenIdx) -> 0 | F8: ASSUMPTION. Multiplies the Capex tab costs.
A9: Lease-up delay (months, pipeline tenants only) | B9: 0 | C9: 0 | D9: 6 | E9: =INDEX($B9:$D9,ScenIdx) -> 0 | F9: ASSUMPTION. Pushes out the start month of every 'Pipeline' tenant on RentRoll.
A11: Active scenario (set on Dashboard) | B11: =Dashboard!$D$4 -> Base
A12: Scenario index | B12: =MATCH(B11,$B$4:$D$4,0) -> 1
A14: ACQUISITION & HOLD
A15: Property | B15: 3879 Rendon Rd | F15: Per Kenny's email.
A16: Total site acres | B16: 37 | F16: Per email: approx. 37 acres.
A17: Purchase price (INPUT) | B17: 5500000 | F17: PLACEHOLDER. No price was given in the email. Type over this; the solved price below does not depend on it.
A18: Price per acre (check) | B18: =PurchPrice/Acres -> 148648.65 | F18: Formula.
A19: Comp value per acre (check) | B19: 150000 | F19: PLACEHOLDER. Replace with IOS land/improved comps.
A20: Implied value at comp $/acre | B20: =CompPerAcre*Acres -> 5550000 | F20: Formula. Compare with the input price and the solved price.
A21: Closing costs (% of price) | B21: 0.015 | F21: ASSUMPTION.
A22: Sale costs (% of exit value) | B22: 0.02 | F22: ASSUMPTION.
A23: Hold period (years, 1-10) | B23: 7 | F23: 7 years per your selection. Changing it re-times the exit everywhere.
A24: Target unlevered IRR (drives solved price) | B24: 0.1 | F24: PLACEHOLDER. Your return hurdle.
A25: Target levered IRR (dashboard flag) | B25: 0.15 | F25: PLACEHOLDER. Your return hurdle.
A26: Minimum DSCR (dashboard flag) | B26: 1.25 | F26: PLACEHOLDER. Typical lender floor.
A27: Sensitivity step: rent growth (+/-) | B27: 0.01 | F27: Spacing of the sensitivity grid rows.
A28: Sensitivity step: exit cap (+/-) | B28: 0.005 | F28: Spacing of the sensitivity grid columns.
A30: OPERATING EXPENSES (start from seller's numbers; every line editable)
A31: Seller property tax (annual) | B31: 5000 | F31: Email: taxes + liability insurance about $7,000 total. The $5,000 / $2,000 split is an ASSUMPTION; confirm.
A32: Liability insurance (annual) | B32: 2000 | F32: See above.
A33: Property tax basis: 0 = seller's current, 1 = reassess at purchase price | B33: 0 | F33: Starts at seller's number as you asked. $7K on 37 acres likely reflects a low/ag appraisal; set to 1 to see reassessment.
A34: Reassessed tax rate (% of purchase price) | B34: 0.022 | F34: PLACEHOLDER. Confirm combined county/ISD/city rate for the site.
A35: Management fee (% of effective gross revenue) | B35: 0 | F35: Seller shows none. Raise to underwrite third-party management.
A36: Capital reserves ($ per acre per year) | B36: 0 | F36: Seller shows none. Raise to underwrite reserves.
A37: Other opex / repairs ($ per year) | B37: 0 | F37: Seller shows none (Reindeer pays electric).
A38: Expense growth (annual) | B38: 0.03 | F38: ASSUMPTION.
A40: FINANCING (buyer-side; seller owns free and clear)
A41: Use leverage? (1 = yes, 0 = unlevered only) | B41: 1 | F41: Set to 0 to zero out the loan.
A42: Loan-to-value (% of purchase price) | B42: 0.55 | F42: PLACEHOLDER. You said you'd supply terms.
A43: Interest rate | B43: 0.0675 | F43: PLACEHOLDER. Must be above 0%.
A44: Amortization (years) | B44: 25 | F44: PLACEHOLDER.
A45: Interest-only period (years) | B45: 2 | F45: PLACEHOLDER.
...

Sheet RentRoll
A1: Rent Roll — Every Tenant Is a Line Item
A2: Each tenant has an Include % per scenario (cols M-O). The Dashboard toggle picks which column drives the cash flow. Months are counted from closing. Blank bump = market rent growth. Blank lease end = month-to-month / no stated term.
A3: Blue text = input · Dotted underline = assumption to confirm. Example of format: rent 13,000, period Monthly, start 0, lease end 60.
A5: # | B5: Tenant | C5: Status | D5: Space / terms (from email) | E5: Acres | F5: Rent ($) | G5: Rent period | H5: Annual rent ($) | I5: Annual bump | J5: Start mo. | K5: Lease end mo. | L5: Retention after end | M5: Base incl. | N5: Upside incl. | O5: Downside incl. | P5: Active incl. | Q5: Effective bump | R5: Effective start | S5: Notes / source
A6: 1 | B6: S&A Leasing | C6: In-place | D6: ~5 yrs left on 10-yr lease; small annual increases. Tenant 'takes care of parking clubs'. | F6: 13000 | G6: Monthly | H6: =IF(G6="Annual",F6,F6*12) -> 156000 | I6: 0.03 | J6: 0 | K6: 60 | L6: 0.85 | M6: 1 | N6: 1 | O6: 1 | P6: =INDEX(M6:O6,ScenIdx) -> 1 | Q6: =IF(I6="",RentGrowth,I6) -> 0.03 | R6: =J6+IF(C6="Pipeline",LeaseDelay,0) -> 0 | S6: Email: ~$13,000/mo. 3% bump and 85% post-expiry retention are ASSUMPTIONS. Confirm what 'parking clubs' means for NNN/maintenance.
A7: 2 | B7: Reindeer (Prime) | C7: In-place | D7: 1.56 ac + portion of office; pays electric. 1 month left, wants 1-2 yr renewal. | E7: 1.56 | F7: 7000 | G7: Monthly | H7: =IF(G7="Annual",F7,F7*12) -> 84000 | J7: 0 | K7: 24 | L7: 0.9 | M7: 1 | N7: 1 | O7: 0 | P7: =INDEX(M7:O7,ScenIdx) -> 1 | Q7: =IF(I7="",RentGrowth,I7) -> 0.03 | R7: =J7+IF(C7="Pipeline",LeaseDelay,0) -> 0 | S7: Email: $7,000/mo. Lease end 24 = ASSUMES a 2-yr renewal; downside drops them.
A8: 3 | B8: Straight 6 | C8: In-place | D8: Shop + 1 ac. | E8: 1 | F8: 6500 | G8: Monthly | H8: =IF(G8="Annual",F8,F8*12) -> 78000 | J8: 0 | M8: 1 | N8: 1 | O8: 1 | P8: =INDEX(M8:O8,ScenIdx) -> 1 | Q8: =IF(I8="",RentGrowth,I8) -> 0.03 | R8: =J8+IF(C8="Pipeline",LeaseDelay,0) -> 0 | S8: Email: $6,500/mo. No lease term stated.
A9: 4 | B9: Big Dawgs (repo) | C9: In-place | D9: 2 tiny spots. | F9: 4000 | G9: Monthly | H9: =IF(G9="Annual",F9,F9*12) -> 48000 | J9: 0 | M9: 1 | N9: 1 | O9: 1 | P9: =INDEX(M9:O9,ScenIdx) -> 1 | Q9: =IF(I9="",RentGrowth,I9) -> 0.03 | R9: =J9+IF(C9="Pipeline",LeaseDelay,0) -> 0 | S9: Email: $4,000/mo. No lease term stated.
A10: 5 | B10: Individual tenants (various) | C10: In-place | D10: Vary month to month; 'pretty solid' at $1,700-$2,500/mo. | F10: 2100 | G10: Monthly | H10: =IF(G10="Annual",F10,F10*12) -> 25200 | J10: 0 | M10: 1 | N10: 1 | O10: 0.75 | P10: =INDEX(M10:O10,ScenIdx) -> 1 | Q10: =IF(I10="",RentGrowth,I10) -> 0.03 | R10: =J10+IF(C10="Pipeline",LeaseDelay,0) -> 0 | S10: Email range $1,700-$2,500; midpoint used (ASSUMPTION). Downside haircuts to 75%.
A11: 6 | B11: CDL driver training | C11: In-place | D11: 0.5 ac; with the owner many years. | E11: 0.5 | F11: 1500 | G11: Monthly | H11: =IF(G11="Annual",F11,F11*12) -> 18000 | J11: 0 | M11: 1 | N11: 1 | O11: 1 | P11: =INDEX(M11:O11,ScenIdx) -> 1 | Q11: =IF(I11="",RentGrowth,I11) -> 0.03 | R11: =J11+IF(C11="Pipeline",LeaseDelay,0) -> 0 | S11: Email: $1,500/mo. No lease term stated.
A12: 7 | B12: Alamo Fireworks | C12: In-place | D12: Container by the street; sells July 4 and New Year; leaves it in place. | F12: 8000 | G12: Annual | H12: =IF(G12="Annual",F12,F12*12) -> 8000 | J12: 0 | M12: 1 | N12: 1 | O12: 1 | P12: =INDEX(M12:O12,ScenIdx) -> 1 | Q12: =IF(I12="",RentGrowth,I12) -> 0.03 | R12: =J12+IF(C12="Pipeline",LeaseDelay,0) -> 0 | S12: Email: $8,000 per YEAR.
A13: 8 | B13: Prime expansion (+1 ac) | C13: Pipeline | D13: Prime adding 1 more acre. | E13: 1 | F13: 3500 | G13: Monthly | H13: =IF(G13="Annual",F13,F13*12) -> 42000 | J13: 3 | M13: 1 | N13: 1 | O13: 0 | P13: =INDEX(M13:O13,ScenIdx) -> 1 | Q13: =IF(I13="",RentGrowth,I13) -> 0.03 | R13: =J13+IF(C13="Pipeline",LeaseDelay,0) -> 3 | S13: Email: +$3,500/mo. Start month 3 is an ASSUMPTION.
A14: 9 | B14: Straight 6 expansion (~10 spots) | C14: Pipeline | D14: About 10 added spots. | F14: 1000 | G14: Monthly | H14: =IF(G14="Annual",F14,F14*12) -> 12000 | J14: 3 | M14: 1 | N14: 1 | O14: 0 | P14: =INDEX(M14:O14,ScenIdx) -> 1 | Q14: =IF(I14="",RentGrowth,I14) -> 0.03 | R14: =J14+IF(C14="Pipeline",LeaseDelay,0) -> 3 | S14: Email: +$1,000/mo. Start month 3 is an ASSUMPTION.
A15: 10 | B15: Large tenant (~5.75 ac, in county) | C15: Pipeline | D15: Big company, at least 1 year, in county, 'a great lot'. Not yet signed. | E15: 5.75 | F15: 20000 | G15: Monthly | H15: =IF(G15="Annual",F15,F15*12) -> 240000 | J15: 6 | K15: 18 | L15: 0.7 | M15: 0 | N15: 1 | O15: 0 | P15: =INDEX(M15:O15,ScenIdx) -> 0 | Q15: =IF(I15="",RentGrowth,I15) -> 0.03 | R15: =J15+IF(C15="Pipeline",LeaseDelay,0) -> 6 | S15: Email: $20,000/mo for at least 1 yr. Base = 0% (upside only); change M15 to bring it into base. Start 6 / end 18 / 70% retention are ASSUMPTIONS.
B17: POTENTIAL BASE REVENUE: all tenants at 100% (annual run-rate) | H17: =SUM(H6:H15) -> 711200
B18: of which in-place | H18: =SUMIF(C6:C15,"In-place",H6:H15) -> 417200
B19: of which pipeline | H19: =SUMIF(C6:C15,"Pipeline",H6:H15) -> 294000
B20: Revenue included in active scenario (annual run-rate) | H20: =SUMPRODUCT(H6:H15,P6:P15) -> 471200
B22: Acres itemized in email (in-place tenants) | H22: =SUMIF(C6:C15,"In-place",E6:E15) -> 3.06
B23: Total site acres | H23: =Acres -> 37
B24: Site acres not itemized in email | H24: =H23-H22 -> 33.94 | S24: Includes buildings, drive aisles, spots with no acreage given, and any vacant land. Confirm vacant acreage; it drives lease-up upside.

Sheet Capex
A1: Capex — Lease-Up and Site Improvements
A2: All amounts are PLACEHOLDERS (the email gave no capex figures). Rent from these improvements is captured by the tenant lines on RentRoll.
A3: Include flags are 1/0 per scenario. Year = year incurred (1-10). Example format: cost 35,000 per acre x 5.75 acres in Year 1.
A5: Item | B5: Unit | C5: Unit cost ($) | D5: Units | E5: Year | F5: Gross cost ($) | G5: Base | H5: Upside | I5: Downside | J5: Active | K5: Scenario cost ($) | L5: Notes
A6: Gravel/paving & grading: large tenant lot | B6: $/acre | C6: 35000 | D6: =RentRoll!E15 -> 5.75 | E6: 1 | F6: =C6*D6 -> 201250 | G6: 0 | H6: 1 | I6: 0 | J6: =INDEX($G6:$I6,ScenIdx) -> 0 | K6: =F6*J6*(1+CapexOverrun) -> 0 | L6: Acres link to the large tenant line. Only built if that tenant is in the scenario.
A7: Gravel/paving: Prime +1 ac & Straight 6 spots | B7: $/acre | C7: 35000 | D7: 1.5 | E7: 1 | F7: =C7*D7 -> 52500 | G7: 1 | H7: 1 | I7: 0 | J7: =INDEX($G7:$I7,ScenIdx) -> 1 | K7: =F7*J7*(1+CapexOverrun) -> 52500 | L7: 1.5 acres is an ASSUMPTION (1 ac Prime + ~0.5 ac for ~10 spots).
A8: Perimeter fencing & gates | B8: lump sum | C8: 60000 | D8: 1 | E8: 1 | F8: =C8*D8 -> 60000 | G8: 1 | H8: 1 | I8: 1 | J8: =INDEX($G8:$I8,ScenIdx) -> 1 | K8: =F8*J8*(1+CapexOverrun) -> 60000 | L8: PLACEHOLDER.
A9: Site lighting | B9: lump sum | C9: 45000 | D9: 1 | E9: 2 | F9: =C9*D9 -> 45000 | G9: 1 | H9: 1 | I9: 1 | J9: =INDEX($G9:$I9,ScenIdx) -> 1 | K9: =F9*J9*(1+CapexOverrun) -> 45000 | L9: PLACEHOLDER.
A10: TOTAL | F10: =SUM(F6:F9) -> 358750 | K10: =SUM(K6:K9) -> 157500

Sheet CashFlow
A1: Annual DCF — 3879 Rendon Rd
A2: ="Scenario: "&Inputs!$B$11&" | Hold: "&Hold&" yrs | Year 0 = closing; Year 11 is only used as the forward NOI for a Year-10 exit" -> Scenario: Base | Hold: 7 yrs | Year 0 = closing; Year 11 is only used as the forward NOI for a Year-10 exit
A4: Year | C4: 0 | D4: =C4+1 -> 1 | E4: =D4+1 -> 2 | F4: =E4+1 -> 3 | G4: =F4+1 -> 4 | H4: =G4+1 -> 5 | I4: =H4+1 -> 6 | J4: =I4+1 -> 7 | K4: =J4+1 -> 8 | ... N4: =M4+1 -> 11
A5: In hold period (1/0) | D5: =IF(AND(D$4>=1,D$4<=Hold),1,0) -> 1 | E5: =IF(AND(E$4>=1,E$4<=Hold),1,0) -> 1 | F5: =IF(AND(F$4>=1,F$4<=Hold),1,0) -> 1 | G5: =IF(AND(G$4>=1,G$4<=Hold),1,0) -> 1 | H5: =IF(AND(H$4>=1,H$4<=Hold),1,0) -> 1 | I5: =IF(AND(I$4>=1,I$4<=Hold),1,0) -> 1 | J5: =IF(AND(J$4>=1,J$4<=Hold),1,0) -> 1 | K5: =IF(AND(K$4>=1,K$4<=Hold),1,0) -> 0 | ... N5: =IF(AND(N$4>=1,N$4<=Hold),1,0) -> 0
A6: Exit year flag (1/0) | D6: =IF(D$4=Hold,1,0) -> 0 | E6: =IF(E$4=Hold,1,0) -> 0 | F6: =IF(F$4=Hold,1,0) -> 0 | G6: =IF(G$4=Hold,1,0) -> 0 | H6: =IF(H$4=Hold,1,0) -> 0 | I6: =IF(I$4=Hold,1,0) -> 0 | J6: =IF(J$4=Hold,1,0) -> 1 | K6: =IF(K$4=Hold,1,0) -> 0 | ... N6: =IF(N$4=Hold,1,0) -> 0
A8: REVENUE (included in active scenario; one line per tenant)
A9: =RentRoll!B6 -> S&A Leasing | D9: =RentRoll!$H$6*RentRoll!$P$6*(1+RentRoll!$Q$6)^(D$4-1)*(MAX(0,MIN(12*D$4,IF(RentRoll!$K$6="",99999,RentRoll!$K$6))-MAX(12*(D$4-1),RentRoll!$R$6))+RentRoll!$L$6*MAX(0,12*D$4-MAX(12*(D$4-1),IF(RentRoll!$K$6="",99999,RentRoll!$K$6),RentRoll!$R$6)))/12 -> 156000 | E9: =RentRoll!$H$6*RentRoll!$P$6*(1+RentRoll!$Q$6)^(E$4-1)*(MAX(0,MIN(12*E$4,IF(RentRoll!$K$6="",99999,RentRoll!$K$6))-MAX(12*(E$4-1),RentRoll!$R$6))+RentRoll!$L$6*MAX(0,12*E$4-MAX(12*(E$4-1),IF(RentRoll!$K$6="",99999,RentRoll!$K$6),RentRoll!$R$6)))/12 -> 160680 | F9: =RentRoll!$H$6*RentRoll!$P$6*(1+RentRoll!$Q$6)^(F$4-1)*(MAX(0,MIN(12*F$4,IF(RentRoll!$K$6="",99999,RentRoll!$K$6))-MAX(12*(F$4-1),RentRoll!$R$6))+RentRoll!$L$6*MAX(0,12*F$4-MAX(12*(F$4-1),IF(RentRoll!$K$6="",99999,RentRoll!$K$6),RentRoll!$R$6)))/12 -> 165500.4 | G9: =RentRoll!$H$6*RentRoll!$P$6*(1+RentRoll!$Q$6)^(G$4-1)*(MAX(0,MIN(12*G$4,IF(RentRoll!$K$6="",99999,RentRoll!$K$6))-MAX(12*(G$4-1),RentRoll!$R$6))+RentRoll!$L$6*MAX(0,12*G$4-MAX(12*(G$4-1),IF(RentRoll!$K$6="",99999,RentRoll!$K$6),RentRoll!$R$6)))/12 -> 170465.41 | H9: =RentRoll!$H$6*RentRoll!$P$6*(1+RentRoll!$Q$6)^(H$4-1)*(MAX(0,MIN(12*H$4,IF(RentRoll!$K$6="",99999,RentRoll!$K$6))-MAX(12*(H$4-1),RentRoll!$R$6))+RentRoll!$L$6*MAX(0,12*H$4-MAX(12*(H$4-1),IF(RentRoll!$K$6="",99999,RentRoll!$K$6),RentRoll!$R$6)))/12 -> 175579.37 | I9: =RentRoll!$H$6*RentRoll!$P$6*(1+RentRoll!$Q$6)^(I$4-1)*(MAX(0,MIN(12*I$4,IF(RentRoll!$K$6="",99999,RentRoll!$K$6))-MAX(12*(I$4-1),RentRoll!$R$6))+RentRoll!$L$6*MAX(0,12*I$4-MAX(12*(I$4-1),IF(RentRoll!$K$6="",99999,RentRoll!$K$6),RentRoll!$R$6)))/12 -> 153719.74 | J9: =RentRoll!$H$6*RentRoll!$P$6*(1+RentRoll!$Q$6)^(J$4-1)*(MAX(0,MIN(12*J$4,IF(RentRoll!$K$6="",99999,RentRoll!$K$6))-MAX(12*(J$4-1),RentRoll!$R$6))+RentRoll!$L$6*MAX(0,12*J$4-MAX(12*(J$4-1),IF(RentRoll!$K$6="",99999,RentRoll!$K$6),RentRoll!$R$6)))/12 -> 158331.33 | K9: =RentRoll!$H$6*RentRoll!$P$6*(1+RentRoll!$Q$6)^(K$4-1)*(MAX(0,MIN(12*K$4,IF(RentRoll!$K$6="",99999,RentRoll!$K$6))-MAX(12*(K$4-1),RentRoll!$R$6))+RentRoll!$L$6*MAX(0,12*K$4-MAX(12*(K$4-1),IF(RentRoll!$K$6="",99999,RentRoll!$K$6),RentRoll!$R$6)))/12 -> 163081.27 | ... N9: =RentRoll!$H$6*RentRoll!$P$6*(1+RentRoll!$Q$6)^(N$4-1)*(MAX(0,MIN(12*N$4,IF(RentRoll!$K$6="",99999,RentRoll!$K$6))-MAX(12*(N$4-1),RentRoll!$R$6))+RentRoll!$L$6*MAX(0,12*N$4-MAX(12*(N$4-1),IF(RentRoll!$K$6="",99999,RentRoll!$K$6),RentRoll!$R$6)))/12 -> 178203.31
A10: =RentRoll!B7 -> Reindeer (Prime) | D10: =RentRoll!$H$7*RentRoll!$P$7*(1+RentRoll!$Q$7)^(D$4-1)*(MAX(0,MIN(12*D$4,IF(RentRoll!$K$7="",99999,RentRoll!$K$7))-MAX(12*(D$4-1),RentRoll!$R$7))+RentRoll!$L$7*MAX(0,12*D$4-MAX(12*(D$4-1),IF(RentRoll!$K$7="",99999,RentRoll!$K$7),RentRoll!$R$7)))/12 -> 84000 | E10: =RentRoll!$H$7*RentRoll!$P$7*(1+RentRoll!$Q$7)^(E$4-1)*(MAX(0,MIN(12*E$4,IF(RentRoll!$K$7="",99999,RentRoll!$K$7))-MAX(12*(E$4-1),RentRoll!$R$7))+RentRoll!$L$7*MAX(0,12*E$4-MAX(12*(E$4-1),IF(RentRoll!$K$7="",99999,RentRoll!$K$7),RentRoll!$R$7)))/12 -> 86520 | F10: =RentRoll!$H$7*RentRoll!$P$7*(1+RentRoll!$Q$7)^(F$4-1)*(MAX(0,MIN(12*F$4,IF(RentRoll!$K$7="",99999,RentRoll!$K$7))-MAX(12*(F$4-1),RentRoll!$R$7))+RentRoll!$L$7*MAX(0,12*F$4-MAX(12*(F$4-1),IF(RentRoll!$K$7="",99999,RentRoll!$K$7),RentRoll!$R$7)))/12 -> 80204.04 | G10: =RentRoll!$H$7*RentRoll!$P$7*(1+RentRoll!$Q$7)^(G$4-1)*(MAX(0,MIN(12*G$4,IF(RentRoll!$K$7="",99999,RentRoll!$K$7))-MAX(12*(G$4-1),RentRoll!$R$7))+RentRoll!$L$7*MAX(0,12*G$4-MAX(12*(G$4-1),IF(RentRoll!$K$7="",99999,RentRoll!$K$7),RentRoll!$R$7)))/12 -> 82610.161 | H10: =RentRoll!$H$7*RentRoll!$P$7*(1+RentRoll!$Q$7)^(H$4-1)*(MAX(0,MIN(12*H$4,IF(RentRoll!$K$7="",99999,RentRoll!$K$7))-MAX(12*(H$4-1),RentRoll!$R$7))+RentRoll!$L$7*MAX(0,12*H$4-MAX(12*(H$4-1),IF(RentRoll!$K$7="",99999,RentRoll!$K$7),RentRoll!$R$7)))/12 -> 85088.466 | I10: =RentRoll!$H$7*RentRoll!$P$7*(1+RentRoll!$Q$7)^(I$4-1)*(MAX(0,MIN(12*I$4,IF(RentRoll!$K$7="",99999,RentRoll!$K$7))-MAX(12*(I$4-1),RentRoll!$R$7))+RentRoll!$L$7*MAX(0,12*I$4-MAX(12*(I$4-1),IF(RentRoll!$K$7="",99999,RentRoll!$K$7),RentRoll!$R$7)))/12 -> 87641.12 | J10: =RentRoll!$H$7*RentRoll!$P$7*(1+RentRoll!$Q$7)^(J$4-1)*(MAX(0,MIN(12*J$4,IF(RentRoll!$K$7="",99999,RentRoll!$K$7))-MAX(12*(J$4-1),RentRoll!$R$7))+RentRoll!$L$7*MAX(0,12*J$4-MAX(12*(J$4-1),IF(RentRoll!$K$7="",99999,RentRoll!$K$7),RentRoll!$R$7)))/12 -> 90270.354 | K10: =RentRoll!$H$7*RentRoll!$P$7*(1+RentRoll!$Q$7)^(K$4-1)*(MAX(0,MIN(12*K$4,IF(RentRoll!$K$7="",99999,RentRoll!$K$7))-MAX(12*(K$4-1),RentRoll!$R$7))+RentRoll!$L$7*MAX(0,12*K$4-MAX(12*(K$4-1),IF(RentRoll!$K$7="",99999,RentRoll!$K$7),RentRoll!$R$7)))/12 -> 92978.464 | ... N10: =RentRoll!$H$7*RentRoll!$P$7*(1+RentRoll!$Q$7)^(N$4-1)*(MAX(0,MIN(12*N$4,IF(RentRoll!$K$7="",99999,RentRoll!$K$7))-MAX(12*(N$4-1),RentRoll!$R$7))+RentRoll!$L$7*MAX(0,12*N$4-MAX(12*(N$4-1),IF(RentRoll!$K$7="",99999,RentRoll!$K$7),RentRoll!$R$7)))/12 -> 101600.08
A11: =RentRoll!B8 -> Straight 6 | D11: =RentRoll!$H$8*RentRoll!$P$8*(1+RentRoll!$Q$8)^(D$4-1)*(MAX(0,MIN(12*D$4,IF(RentRoll!$K$8="",99999,RentRoll!$K$8))-MAX(12*(D$4-1),RentRoll!$R$8))+RentRoll!$L$8*MAX(0,12*D$4-MAX(12*(D$4-1),IF(RentRoll!$K$8="",99999,RentRoll!$K$8),RentRoll!$R$8)))/12 -> 78000 | E11: =RentRoll!$H$8*RentRoll!$P$8*(1+RentRoll!$Q$8)^(E$4-1)*(MAX(0,MIN(12*E$4,IF(RentRoll!$K$8="",99999,RentRoll!$K$8))-MAX(12*(E$4-1),RentRoll!$R$8))+RentRoll!$L$8*MAX(0,12*E$4-MAX(12*(E$4-1),IF(RentRoll!$K$8="",99999,RentRoll!$K$8),RentRoll!$R$8)))/12 -> 80340 | F11: =RentRoll!$H$8*RentRoll!$P$8*(1+RentRoll!$Q$8)^(F$4-1)*(MAX(0,MIN(12*F$4,IF(RentRoll!$K$8="",99999,RentRoll!$K$8))-MAX(12*(F$4-1),RentRoll!$R$8))+RentRoll!$L$8*MAX(0,12*F$4-MAX(12*(F$4-1),IF(RentRoll!$K$8="",99999,RentRoll!$K$8),RentRoll!$R$8)))/12 -> 82750.2 | G11: =RentRoll!$H$8*RentRoll!$P$8*(1+RentRoll!$Q$8)^(G$4-1)*(MAX(0,MIN(12*G$4,IF(RentRoll!$K$8="",99999,RentRoll!$K$8))-MAX(12*(G$4-1),RentRoll!$R$8))+RentRoll!$L$8*MAX(0,12*G$4-MAX(12*(G$4-1),IF(RentRoll!$K$8="",99999,RentRoll!$K$8),RentRoll!$R$8)))/12 -> 85232.706 | H11: =RentRoll!$H$8*RentRoll!$P$8*(1+RentRoll!$Q$8)^(H$4-1)*(MAX(0,MIN(12*H$4,IF(RentRoll!$K$8="",99999,RentRoll!$K$8))-MAX(12*(H$4-1),RentRoll!$R$8))+RentRoll!$L$8*MAX(0,12*H$4-MAX(12*(H$4-1),IF(RentRoll!$K$8="",99999,RentRoll!$K$8),RentRoll!$R$8)))/12 -> 87789.687 | I11: =RentRoll!$H$8*RentRoll!$P$8*(1+RentRoll!$Q$8)^(I$4-1)*(MAX(0,MIN(12*I$4,IF(RentRoll!$K$8="",99999,RentRoll!$K$8))-MAX(12*(I$4-1),RentRoll!$R$8))+RentRoll!$L$8*MAX(0,12*I$4-MAX(12*(I$4-1),IF(RentRoll!$K$8="",99999,RentRoll!$K$8),RentRoll!$R$8)))/12 -> 90423.378 | J11: =RentRoll!$H$8*RentRoll!$P$8*(1+RentRoll!$Q$8)^(J$4-1)*(MAX(0,MIN(12*J$4,IF(RentRoll!$K$8="",99999,RentRoll!$K$8))-MAX(12*(J$4-1),RentRoll!$R$8))+RentRoll!$L$8*MAX(0,12*J$4-MAX(12*(J$4-1),IF(RentRoll!$K$8="",99999,RentRoll!$K$8),RentRoll!$R$8)))/12 -> 93136.079 | K11: =RentRoll!$H$8*RentRoll!$P$8*(1+RentRoll!$Q$8)^(K$4-1)*(MAX(0,MIN(12*K$4,IF(RentRoll!$K$8="",99999,RentRoll!$K$8))-MAX(12*(K$4-1),RentRoll!$R$8))+RentRoll!$L$8*MAX(0,12*K$4-MAX(12*(K$4-1),IF(RentRoll!$K$8="",99999,RentRoll!$K$8),RentRoll!$R$8)))/12 -> 95930.162 | ... N11: =RentRoll!$H$8*RentRoll!$P$8*(1+RentRoll!$Q$8)^(N$4-1)*(MAX(0,MIN(12*N$4,IF(RentRoll!$K$8="",99999,RentRoll!$K$8))-MAX(12*(N$4-1),RentRoll!$R$8))+RentRoll!$L$8*MAX(0,12*N$4-MAX(12*(N$4-1),IF(RentRoll!$K$8="",99999,RentRoll!$K$8),RentRoll!$R$8)))/12 -> 104825.48
A12: =RentRoll!B9 -> Big Dawgs (repo) | D12: =RentRoll!$H$9*RentRoll!$P$9*(1+RentRoll!$Q$9)^(D$4-1)*(MAX(0,MIN(12*D$4,IF(RentRoll!$K$9="",99999,RentRoll!$K$9))-MAX(12*(D$4-1),RentRoll!$R$9))+RentRoll!$L$9*MAX(0,12*D$4-MAX(12*(D$4-1),IF(RentRoll!$K$9="",99999,RentRoll!$K$9),RentRoll!$R$9)))/12 -> 48000 | E12: =RentRoll!$H$9*RentRoll!$P$9*(1+RentRoll!$Q$9)^(E$4-1)*(MAX(0,MIN(12*E$4,IF(RentRoll!$K$9="",99999,RentRoll!$K$9))-MAX(12*(E$4-1),RentRoll!$R$9))+RentRoll!$L$9*MAX(0,12*E$4-MAX(12*(E$4-1),IF(RentRoll!$K$9="",99999,RentRoll!$K$9),RentRoll!$R$9)))/12 -> 49440 | F12: =RentRoll!$H$9*RentRoll!$P$9*(1+RentRoll!$Q$9)^(F$4-1)*(MAX(0,MIN(12*F$4,IF(RentRoll!$K$9="",99999,RentRoll!$K$9))-MAX(12*(F$4-1),RentRoll!$R$9))+RentRoll!$L$9*MAX(0,12*F$4-MAX(12*(F$4-1),IF(RentRoll!$K$9="",99999,RentRoll!$K$9),RentRoll!$R$9)))/12 -> 50923.2 | G12: =RentRoll!$H$9*RentRoll!$P$9*(1+RentRoll!$Q$9)^(G$4-1)*(MAX(0,MIN(12*G$4,IF(RentRoll!$K$9="",99999,RentRoll!$K$9))-MAX(12*(G$4-1),RentRoll!$R$9))+RentRoll!$L$9*MAX(0,12*G$4-MAX(12*(G$4-1),IF(RentRoll!$K$9="",99999,RentRoll!$K$9),RentRoll!$R$9)))/12 -> 52450.896 | H12: =RentRoll!$H$9*RentRoll!$P$9*(1+RentRoll!$Q$9)^(H$4-1)*(MAX(0,MIN(12*H$4,IF(RentRoll!$K$9="",99999,RentRoll!$K$9))-MAX(12*(H$4-1),RentRoll!$R$9))+RentRoll!$L$9*MAX(0,12*H$4-MAX(12*(H$4-1),IF(RentRoll!$K$9="",99999,RentRoll!$K$9),RentRoll!$R$9)))/12 -> 54024.423 | I12: =RentRoll!$H$9*RentRoll!$P$9*(1+RentRoll!$Q$9)^(I$4-1)*(MAX(0,MIN(12*I$4,IF(RentRoll!$K$9="",99999,RentRoll!$K$9))-MAX(12*(I$4-1),RentRoll!$R$9))+RentRoll!$L$9*MAX(0,12*I$4-MAX(12*(I$4-1),IF(RentRoll!$K$9="",99999,RentRoll!$K$9),RentRoll!$R$9)))/12 -> 55645.156 | J12: =RentRoll!$H$9*RentRoll!$P$9*(1+RentRoll!$Q$9)^(J$4-1)*(MAX(0,MIN(12*J$4,IF(RentRoll!$K$9="",99999,RentRoll!$K$9))-MAX(12*(J$4-1),RentRoll!$R$9))+RentRoll!$L$9*MAX(0,12*J$4-MAX(12*(J$4-1),IF(RentRoll!$K$9="",99999,RentRoll!$K$9),RentRoll!$R$9)))/12 -> 57314.51 | K12: =RentRoll!$H$9*RentRoll!$P$9*(1+RentRoll!$Q$9)^(K$4-1)*(MAX(0,MIN(12*K$4,IF(RentRoll!$K$9="",99999,RentRoll!$K$9))-MAX(12*(K$4-1),RentRoll!$R$9))+RentRoll!$L$9*MAX(0,12*K$4-MAX(12*(K$4-1),IF(RentRoll!$K$9="",99999,RentRoll!$K$9),RentRoll!$R$9)))/12 -> 59033.946 | ... N12: =RentRoll!$H$9*RentRoll!$P$9*(1+RentRoll!$Q$9)^(N$4-1)*(MAX(0,MIN(12*N$4,IF(RentRoll!$K$9="",99999,RentRoll!$K$9))-MAX(12*(N$4-1),RentRoll!$R$9))+RentRoll!$L$9*MAX(0,12*N$4-MAX(12*(N$4-1),IF(RentRoll!$K$9="",99999,RentRoll!$K$9),RentRoll!$R$9)))/12 -> 64507.986
A13: =RentRoll!B10 -> Individual tenants (various) | D13: =RentRoll!$H$10*RentRoll!$P$10*(1+RentRoll!$Q$10)^(D$4-1)*(MAX(0,MIN(12*D$4,IF(RentRoll!$K$10="",99999,RentRoll!$K$10))-MAX(12*(D$4-1),RentRoll!$R$10))+RentRoll!$L$10*MAX(0,12*D$4-MAX(12*(D$4-1),IF(RentRoll!$K$10="",99999,RentRoll!$K$10),RentRoll!$R$10)))/12 -> 25200 | E13: =RentRoll!$H$10*RentRoll!$P$10*(1+RentRoll!$Q$10)^(E$4-1)*(MAX(0,MIN(12*E$4,IF(RentRoll!$K$10="",99999,RentRoll!$K$10))-MAX(12*(E$4-1),RentRoll!$R$10))+RentRoll!$L$10*MAX(0,12*E$4-MAX(12*(E$4-1),IF(RentRoll!$K$10="",99999,RentRoll!$K$10),RentRoll!$R$10)))/12 -> 25956 | F13: =RentRoll!$H$10*RentRoll!$P$10*(1+RentRoll!$Q$10)^(F$4-1)*(MAX(0,MIN(12*F$4,IF(RentRoll!$K$10="",99999,RentRoll!$K$10))-MAX(12*(F$4-1),RentRoll!$R$10))+RentRoll!$L$10*MAX(0,12*F$4-MAX(12*(F$4-1),IF(RentRoll!$K$10="",99999,RentRoll!$K$10),RentRoll!$R$10)))/12 -> 26734.68 | G13: =RentRoll!$H$10*RentRoll!$P$10*(1+RentRoll!$Q$10)^(G$4-1)*(MAX(0,MIN(12*G$4,IF(RentRoll!$K$10="",99999,RentRoll!$K$10))-MAX(12*(G$4-1),RentRoll!$R$10))+RentRoll!$L$10*MAX(0,12*G$4-MAX(12*(G$4-1),IF(RentRoll!$K$10="",99999,RentRoll!$K$10),RentRoll!$R$10)))/12 -> 27536.72 | H13: =RentRoll!$H$10*RentRoll!$P$10*(1+RentRoll!$Q$10)^(H$4-1)*(MAX(0,MIN(12*H$4,IF(RentRoll!$K$10="",99999,RentRoll!$K$10))-MAX(12*(H$4-1),RentRoll!$R$10))+RentRoll!$L$10*MAX(0,12*H$4-MAX(12*(H$4-1),IF(RentRoll!$K$10="",99999,RentRoll!$K$10),RentRoll!$R$10)))/12 -> 28362.822 | I13: =RentRoll!$H$10*RentRoll!$P$10*(1+RentRoll!$Q$10)^(I$4-1)*(MAX(0,MIN(12*I$4,IF(RentRoll!$K$10="",99999,RentRoll!$K$10))-MAX(12*(I$4-1),RentRoll!$R$10))+RentRoll!$L$10*MAX(0,12*I$4-MAX(12*(I$4-1),IF(RentRoll!$K$10="",99999,RentRoll!$K$10),RentRoll!$R$10)))/12 -> 29213.707 | J13: =RentRoll!$H$10*RentRoll!$P$10*(1+RentRoll!$Q$10)^(J$4-1)*(MAX(0,MIN(12*J$4,IF(RentRoll!$K$10="",99999,RentRoll!$K$10))-MAX(12*(J$4-1),RentRoll!$R$10))+RentRoll!$L$10*MAX(0,12*J$4-MAX(12*(J$4-1),IF(RentRoll!$K$10="",99999,RentRoll!$K$10),RentRoll!$R$10)))/12 -> 30090.118 | K13: =RentRoll!$H$10*RentRoll!$P$10*(1+RentRoll!$Q$10)^(K$4-1)*(MAX(0,MIN(12*K$4,IF(RentRoll!$K$10="",99999,RentRoll!$K$10))-MAX(12*(K$4-1),RentRoll!$R$10))+RentRoll!$L$10*MAX(0,12*K$4-MAX(12*(K$4-1),IF(RentRoll!$K$10="",99999,RentRoll!$K$10),RentRoll!$R$10)))/12 -> 30992.821 | ... N13: =RentRoll!$H$10*RentRoll!$P$10*(1+RentRoll!$Q$10)^(N$4-1)*(MAX(0,MIN(12*N$4,IF(RentRoll!$K$10="",99999,RentRoll!$K$10))-MAX(12*(N$4-1),RentRoll!$R$10))+RentRoll!$L$10*MAX(0,12*N$4-MAX(12*(N$4-1),IF(RentRoll!$K$10="",99999,RentRoll!$K$10),RentRoll!$R$10)))/12 -> 33866.693
A14: =RentRoll!B11 -> CDL driver training | D14: =RentRoll!$H$11*RentRoll!$P$11*(1+RentRoll!$Q$11)^(D$4-1)*(MAX(0,MIN(12*D$4,IF(RentRoll!$K$11="",99999,RentRoll!$K$11))-MAX(12*(D$4-1),RentRoll!$R$11))+RentRoll!$L$11*MAX(0,12*D$4-MAX(12*(D$4-1),IF(RentRoll!$K$11="",99999,RentRoll!$K$11),RentRoll!$R$11)))/12 -> 18000 | E14: =RentRoll!$H$11*RentRoll!$P$11*(1+RentRoll!$Q$11)^(E$4-1)*(MAX(0,MIN(12*E$4,IF(RentRoll!$K$11="",99999,RentRoll!$K$11))-MAX(12*(E$4-1),RentRoll!$R$11))+RentRoll!$L$11*MAX(0,12*E$4-MAX(12*(E$4-1),IF(RentRoll!$K$11="",99999,RentRoll!$K$11),RentRoll!$R$11)))/12 -> 18540 | F14: =RentRoll!$H$11*RentRoll!$P$11*(1+RentRoll!$Q$11)^(F$4-1)*(MAX(0,MIN(12*F$4,IF(RentRoll!$K$11="",99999,RentRoll!$K$11))-MAX(12*(F$4-1),RentRoll!$R$11))+RentRoll!$L$11*MAX(0,12*F$4-MAX(12*(F$4-1),IF(RentRoll!$K$11="",99999,RentRoll!$K$11),RentRoll!$R$11)))/12 -> 19096.2 | G14: =RentRoll!$H$11*RentRoll!$P$11*(1+RentRoll!$Q$11)^(G$4-1)*(MAX(0,MIN(12*G$4,IF(RentRoll!$K$11="",99999,RentRoll!$K$11))-MAX(12*(G$4-1),RentRoll!$R$11))+RentRoll!$L$11*MAX(0,12*G$4-MAX(12*(G$4-1),IF(RentRoll!$K$11="",99999,RentRoll!$K$11),RentRoll!$R$11)))/12 -> 19669.086 | H14: =RentRoll!$H$11*RentRoll!$P$11*(1+RentRoll!$Q$11)^(H$4-1)*(MAX(0,MIN(12*H$4,IF(RentRoll!$K$11="",99999,RentRoll!$K$11))-MAX(12*(H$4-1),RentRoll!$R$11))+RentRoll!$L$11*MAX(0,12*H$4-MAX(12*(H$4-1),IF(RentRoll!$K$11="",99999,RentRoll!$K$11),RentRoll!$R$11)))/12 -> 20259.159 | I14: =RentRoll!$H$11*RentRoll!$P$11*(1+RentRoll!$Q$11)^(I$4-1)*(MAX(0,MIN(12*I$4,IF(RentRoll!$K$11="",99999,RentRoll!$K$11))-MAX(12*(I$4-1),RentRoll!$R$11))+RentRoll!$L$11*MAX(0,12*I$4-MAX(12*(I$4-1),IF(RentRoll!$K$11="",99999,RentRoll!$K$11),RentRoll!$R$11)))/12 -> 20866.933 | J14: =RentRoll!$H$11*RentRoll!$P$11*(1+RentRoll!$Q$11)^(J$4-1)*(MAX(0,MIN(12*J$4,IF(RentRoll!$K$11="",99999,RentRoll!$K$11))-MAX(12*(J$4-1),RentRoll!$R$11))+RentRoll!$L$11*MAX(0,12*J$4-MAX(12*(J$4-1),IF(RentRoll!$K$11="",99999,RentRoll!$K$11),RentRoll!$R$11)))/12 -> 21492.941 | K14: =RentRoll!$H$11*RentRoll!$P$11*(1+RentRoll!$Q$11)^(K$4-1)*(MAX(0,MIN(12*K$4,IF(RentRoll!$K$11="",99999,RentRoll!$K$11))-MAX(12*(K$4-1),RentRoll!$R$11))+RentRoll!$L$11*MAX(0,12*K$4-MAX(12*(K$4-1),IF(RentRoll!$K$11="",99999,RentRoll!$K$11),RentRoll!$R$11)))/12 -> 22137.73 | ... N14: =RentRoll!$H$11*RentRoll!$P$11*(1+RentRoll!$Q$11)^(N$4-1)*(MAX(0,MIN(12*N$4,IF(RentRoll!$K$11="",99999,RentRoll!$K$11))-MAX(12*(N$4-1),RentRoll!$R$11))+RentRoll!$L$11*MAX(0,12*N$4-MAX(12*(N$4-1),IF(RentRoll!$K$11="",99999,RentRoll!$K$11),RentRoll!$R$11)))/12 -> 24190.495
A15: =RentRoll!B12 -> Alamo Fireworks | D15: =RentRoll!$H$12*RentRoll!$P$12*(1+RentRoll!$Q$12)^(D$4-1)*(MAX(0,MIN(12*D$4,IF(RentRoll!$K$12="",99999,RentRoll!$K$12))-MAX(12*(D$4-1),RentRoll!$R$12))+RentRoll!$L$12*MAX(0,12*D$4-MAX(12*(D$4-1),IF(RentRoll!$K$12="",99999,RentRoll!$K$12),RentRoll!$R$12)))/12 -> 8000 | E15: =RentRoll!$H$12*RentRoll!$P$12*(1+RentRoll!$Q$12)^(E$4-1)*(MAX(0,MIN(12*E$4,IF(RentRoll!$K$12="",99999,RentRoll!$K$12))-MAX(12*(E$4-1),RentRoll!$R$12))+RentRoll!$L$12*MAX(0,12*E$4-MAX(12*(E$4-1),IF(RentRoll!$K$12="",99999,RentRoll!$K$12),RentRoll!$R$12)))/12 -> 8240 | F15: =RentRoll!$H$12*RentRoll!$P$12*(1+RentRoll!$Q$12)^(F$4-1)*(MAX(0,MIN(12*F$4,IF(RentRoll!$K$12="",99999,RentRoll!$K$12))-MAX(12*(F$4-1),RentRoll!$R$12))+RentRoll!$L$12*MAX(0,12*F$4-MAX(12*(F$4-1),IF(RentRoll!$K$12="",99999,RentRoll!$K$12),RentRoll!$R$12)))/12 -> 8487.2 | G15: =RentRoll!$H$12*RentRoll!$P$12*(1+RentRoll!$Q$12)^(G$4-1)*(MAX(0,MIN(12*G$4,IF(RentRoll!$K$12="",99999,RentRoll!$K$12))-MAX(12*(G$4-1),RentRoll!$R$12))+RentRoll!$L$12*MAX(0,12*G$4-MAX(12*(G$4-1),IF(RentRoll!$K$12="",99999,RentRoll!$K$12),RentRoll!$R$12)))/12 -> 8741.816 | H15: =RentRoll!$H$12*RentRoll!$P$12*(1+RentRoll!$Q$12)^(H$4-1)*(MAX(0,MIN(12*H$4,IF(RentRoll!$K$12="",99999,RentRoll!$K$12))-MAX(12*(H$4-1),RentRoll!$R$12))+RentRoll!$L$12*MAX(0,12*H$4-MAX(12*(H$4-1),IF(RentRoll!$K$12="",99999,RentRoll!$K$12),RentRoll!$R$12)))/12 -> 9004.0705 | I15: =RentRoll!$H$12*RentRoll!$P$12*(1+RentRoll!$Q$12)^(I$4-1)*(MAX(0,MIN(12*I$4,IF(RentRoll!$K$12="",99999,RentRoll!$K$12))-MAX(12*(I$4-1),RentRoll!$R$12))+RentRoll!$L$12*MAX(0,12*I$4-MAX(12*(I$4-1),IF(RentRoll!$K$12="",99999,RentRoll!$K$12),RentRoll!$R$12)))/12 -> 9274.1926 | J15: =RentRoll!$H$12*RentRoll!$P$12*(1+RentRoll!$Q$12)^(J$4-1)*(MAX(0,MIN(12*J$4,IF(RentRoll!$K$12="",99999,RentRoll!$K$12))-MAX(12*(J$4-1),RentRoll!$R$12))+RentRoll!$L$12*MAX(0,12*J$4-MAX(12*(J$4-1),IF(RentRoll!$K$12="",99999,RentRoll!$K$12),RentRoll!$R$12)))/12 -> 9552.4184 | K15: =RentRoll!$H$12*RentRoll!$P$12*(1+RentRoll!$Q$12)^(K$4-1)*(MAX(0,MIN(12*K$4,IF(RentRoll!$K$12="",99999,RentRoll!$K$12))-MAX(12*(K$4-1),RentRoll!$R$12))+RentRoll!$L$12*MAX(0,12*K$4-MAX(12*(K$4-1),IF(RentRoll!$K$12="",99999,RentRoll!$K$12),RentRoll!$R$12)))/12 -> 9838.9909 | ... N15: =RentRoll!$H$12*RentRoll!$P$12*(1+RentRoll!$Q$12)^(N$4-1)*(MAX(0,MIN(12*N$4,IF(RentRoll!$K$12="",99999,RentRoll!$K$12))-MAX(12*(N$4-1),RentRoll!$R$12))+RentRoll!$L$12*MAX(0,12*N$4-MAX(12*(N$4-1),IF(RentRoll!$K$12="",99999,RentRoll!$K$12),RentRoll!$R$12)))/12 -> 10751.331
A16: =RentRoll!B13 -> Prime expansion (+1 ac) | D16: =RentRoll!$H$13*RentRoll!$P$13*(1+RentRoll!$Q$13)^(D$4-1)*(MAX(0,MIN(12*D$4,IF(RentRoll!$K$13="",99999,RentRoll!$K$13))-MAX(12*(D$4-1),RentRoll!$R$13))+RentRoll!$L$13*MAX(0,12*D$4-MAX(12*(D$4-1),IF(RentRoll!$K$13="",99999,RentRoll!$K$13),RentRoll!$R$13)))/12 -> 31500 | E16: =RentRoll!$H$13*RentRoll!$P$13*(1+RentRoll!$Q$13)^(E$4-1)*(MAX(0,MIN(12*E$4,IF(RentRoll!$K$13="",99999,RentRoll!$K$13))-MAX(12*(E$4-1),RentRoll!$R$13))+RentRoll!$L$13*MAX(0,12*E$4-MAX(12*(E$4-1),IF(RentRoll!$K$13="",99999,RentRoll!$K$13),RentRoll!$R$13)))/12 -> 43260 | F16: =RentRoll!$H$13*RentRoll!$P$13*(1+RentRoll!$Q$13)^(F$4-1)*(MAX(0,MIN(12*F$4,IF(RentRoll!$K$13="",99999,RentRoll!$K$13))-MAX(12*(F$4-1),RentRoll!$R$13))+RentRoll!$L$13*MAX(0,12*F$4-MAX(12*(F$4-1),IF(RentRoll!$K$13="",99999,RentRoll!$K$13),RentRoll!$R$13)))/12 -> 44557.8 | G16: =RentRoll!$H$13*RentRoll!$P$13*(1+RentRoll!$Q$13)^(G$4-1)*(MAX(0,MIN(12*G$4,IF(RentRoll!$K$13="",99999,RentRoll!$K$13))-MAX(12*(G$4-1),RentRoll!$R$13))+RentRoll!$L$13*MAX(0,12*G$4-MAX(12*(G$4-1),IF(RentRoll!$K$13="",99999,RentRoll!$K$13),RentRoll!$R$13)))/12 -> 45894.534 | H16: =RentRoll!$H$13*RentRoll!$P$13*(1+RentRoll!$Q$13)^(H$4-1)*(MAX(0,MIN(12*H$4,IF(RentRoll!$K$13="",99999,RentRoll!$K$13))-MAX(12*(H$4-1),RentRoll!$R$13))+RentRoll!$L$13*MAX(0,12*H$4-MAX(12*(H$4-1),IF(RentRoll!$K$13="",99999,RentRoll!$K$13),RentRoll!$R$13)))/12 -> 47271.37 | I16: =RentRoll!$H$13*RentRoll!$P$13*(1+RentRoll!$Q$13)^(I$4-1)*(MAX(0,MIN(12*I$4,IF(RentRoll!$K$13="",99999,RentRoll!$K$13))-MAX(12*(I$4-1),RentRoll!$R$13))+RentRoll!$L$13*MAX(0,12*I$4-MAX(12*(I$4-1),IF(RentRoll!$K$13="",99999,RentRoll!$K$13),RentRoll!$R$13)))/12 -> 48689.511 | J16: =RentRoll!$H$13*RentRoll!$P$13*(1+RentRoll!$Q$13)^(J$4-1)*(MAX(0,MIN(12*J$4,IF(RentRoll!$K$13="",99999,RentRoll!$K$13))-MAX(12*(J$4-1),RentRoll!$R$13))+RentRoll!$L$13*MAX(0,12*J$4-MAX(12*(J$4-1),IF(RentRoll!$K$13="",99999,RentRoll!$K$13),RentRoll!$R$13)))/12 -> 50150.196 | K16: =RentRoll!$H$13*RentRoll!$P$13*(1+RentRoll!$Q$13)^(K$4-1)*(MAX(0,MIN(12*K$4,IF(RentRoll!$K$13="",99999,RentRoll!$K$13))-MAX(12*(K$4-1),RentRoll!$R$13))+RentRoll!$L$13*MAX(0,12*K$4-MAX(12*(K$4-1),IF(RentRoll!$K$13="",99999,RentRoll!$K$13),RentRoll!$R$13)))/12 -> 51654.702 | ... N16: =RentRoll!$H$13*RentRoll!$P$13*(1+RentRoll!$Q$13)^(N$4-1)*(MAX(0,MIN(12*N$4,IF(RentRoll!$K$13="",99999,RentRoll!$K$13))-MAX(12*(N$4-1),RentRoll!$R$13))+RentRoll!$L$13*MAX(0,12*N$4-MAX(12*(N$4-1),IF(RentRoll!$K$13="",99999,RentRoll!$K$13),RentRoll!$R$13)))/12 -> 56444.488
A17: =RentRoll!B14 -> Straight 6 expansion (~10 spots) | D17: =RentRoll!$H$14*RentRoll!$P$14*(1+RentRoll!$Q$14)^(D$4-1)*(MAX(0,MIN(12*D$4,IF(RentRoll!$K$14="",99999,RentRoll!$K$14))-MAX(12*(D$4-1),RentRoll!$R$14))+RentRoll!$L$14*MAX(0,12*D$4-MAX(12*(D$4-1),IF(RentRoll!$K$14="",99999,RentRoll!$K$14),RentRoll!$R$14)))/12 -> 9000 | E17: =RentRoll!$H$14*RentRoll!$P$14*(1+RentRoll!$Q$14)^(E$4-1)*(MAX(0,MIN(12*E$4,IF(RentRoll!$K$14="",99999,RentRoll!$K$14))-MAX(12*(E$4-1),RentRoll!$R$14))+RentRoll!$L$14*MAX(0,12*E$4-MAX(12*(E$4-1),IF(RentRoll!$K$14="",99999,RentRoll!$K$14),RentRoll!$R$14)))/12 -> 12360 | F17: =RentRoll!$H$14*RentRoll!$P$14*(1+RentRoll!$Q$14)^(F$4-1)*(MAX(0,MIN(12*F$4,IF(RentRoll!$K$14="",99999,RentRoll!$K$14))-MAX(12*(F$4-1),RentRoll!$R$14))+RentRoll!$L$14*MAX(0,12*F$4-MAX(12*(F$4-1),IF(RentRoll!$K$14="",99999,RentRoll!$K$14),RentRoll!$R$14)))/12 -> 12730.8 | G17: =RentRoll!$H$14*RentRoll!$P$14*(1+RentRoll!$Q$14)^(G$4-1)*(MAX(0,MIN(12*G$4,IF(RentRoll!$K$14="",99999,RentRoll!$K$14))-MAX(12*(G$4-1),RentRoll!$R$14))+RentRoll!$L$14*MAX(0,12*G$4-MAX(12*(G$4-1),IF(RentRoll!$K$14="",99999,RentRoll!$K$14),RentRoll!$R$14)))/12 -> 13112.724 | H17: =RentRoll!$H$14*RentRoll!$P$14*(1+RentRoll!$Q$14)^(H$4-1)*(MAX(0,MIN(12*H$4,IF(RentRoll!$K$14="",99999,RentRoll!$K$14))-MAX(12*(H$4-1),RentRoll!$R$14))+RentRoll!$L$14*MAX(0,12*H$4-MAX(12*(H$4-1),IF(RentRoll!$K$14="",99999,RentRoll!$K$14),RentRoll!$R$14)))/12 -> 13506.106 | I17: =RentRoll!$H$14*RentRoll!$P$14*(1+RentRoll!$Q$14)^(I$4-1)*(MAX(0,MIN(12*I$4,IF(RentRoll!$K$14="",99999,RentRoll!$K$14))-MAX(12*(I$4-1),RentRoll!$R$14))+RentRoll!$L$14*MAX(0,12*I$4-MAX(12*(I$4-1),IF(RentRoll!$K$14="",99999,RentRoll!$K$14),RentRoll!$R$14)))/12 -> 13911.289 | J17: =RentRoll!$H$14*RentRoll!$P$14*(1+RentRoll!$Q$14)^(J$4-1)*(MAX(0,MIN(12*J$4,IF(RentRoll!$K$14="",99999,RentRoll!$K$14))-MAX(12*(J$4-1),RentRoll!$R$14))+RentRoll!$L$14*MAX(0,12*J$4-MAX(12*(J$4-1),IF(RentRoll!$K$14="",99999,RentRoll!$K$14),RentRoll!$R$14)))/12 -> 14328.628 | K17: =RentRoll!$H$14*RentRoll!$P$14*(1+RentRoll!$Q$14)^(K$4-1)*(MAX(0,MIN(12*K$4,IF(RentRoll!$K$14="",99999,RentRoll!$K$14))-MAX(12*(K$4-1),RentRoll!$R$14))+RentRoll!$L$14*MAX(0,12*K$4-MAX(12*(K$4-1),IF(RentRoll!$K$14="",99999,RentRoll!$K$14),RentRoll!$R$14)))/12 -> 14758.486 | ... N17: =RentRoll!$H$14*RentRoll!$P$14*(1+RentRoll!$Q$14)^(N$4-1)*(MAX(0,MIN(12*N$4,IF(RentRoll!$K$14="",99999,RentRoll!$K$14))-MAX(12*(N$4-1),RentRoll!$R$14))+RentRoll!$L$14*MAX(0,12*N$4-MAX(12*(N$4-1),IF(RentRoll!$K$14="",99999,RentRoll!$K$14),RentRoll!$R$14)))/12 -> 16126.997
A18: =RentRoll!B15 -> Large tenant (~5.75 ac, in county) | D18: =RentRoll!$H$15*RentRoll!$P$15*(1+RentRoll!$Q$15)^(D$4-1)*(MAX(0,MIN(12*D$4,IF(RentRoll!$K$15="",99999,RentRoll!$K$15))-MAX(12*(D$4-1),RentRoll!$R$15))+RentRoll!$L$15*MAX(0,12*D$4-MAX(12*(D$4-1),IF(RentRoll!$K$15="",99999,RentRoll!$K$15),RentRoll!$R$15)))/12 -> 0 | E18: =RentRoll!$H$15*RentRoll!$P$15*(1+RentRoll!$Q$15)^(E$4-1)*(MAX(0,MIN(12*E$4,IF(RentRoll!$K$15="",99999,RentRoll!$K$15))-MAX(12*(E$4-1),RentRoll!$R$15))+RentRoll!$L$15*MAX(0,12*E$4-MAX(12*(E$4-1),IF(RentRoll!$K$15="",99999,RentRoll!$K$15),RentRoll!$R$15)))/12 -> 0 | F18: =RentRoll!$H$15*RentRoll!$P$15*(1+RentRoll!$Q$15)^(F$4-1)*(MAX(0,MIN(12*F$4,IF(RentRoll!$K$15="",99999,RentRoll!$K$15))-MAX(12*(F$4-1),RentRoll!$R$15))+RentRoll!$L$15*MAX(0,12*F$4-MAX(12*(F$4-1),IF(RentRoll!$K$15="",99999,RentRoll!$K$15),RentRoll!$R$15)))/12 -> 0 | G18: =RentRoll!$H$15*RentRoll!$P$15*(1+RentRoll!$Q$15)^(G$4-1)*(MAX(0,MIN(12*G$4,IF(RentRoll!$K$15="",99999,RentRoll!$K$15))-MAX(12*(G$4-1),RentRoll!$R$15))+RentRoll!$L$15*MAX(0,12*G$4-MAX(12*(G$4-1),IF(RentRoll!$K$15="",99999,RentRoll!$K$15),RentRoll!$R$15)))/12 -> 0 | H18: =RentRoll!$H$15*RentRoll!$P$15*(1+RentRoll!$Q$15)^(H$4-1)*(MAX(0,MIN(12*H$4,IF(RentRoll!$K$15="",99999,RentRoll!$K$15))-MAX(12*(H$4-1),RentRoll!$R$15))+RentRoll!$L$15*MAX(0,12*H$4-MAX(12*(H$4-1),IF(RentRoll!$K$15="",99999,RentRoll!$K$15),RentRoll!$R$15)))/12 -> 0 | I18: =RentRoll!$H$15*RentRoll!$P$15*(1+RentRoll!$Q$15)^(I$4-1)*(MAX(0,MIN(12*I$4,IF(RentRoll!$K$15="",99999,RentRoll!$K$15))-MAX(12*(I$4-1),RentRoll!$R$15))+RentRoll!$L$15*MAX(0,12*I$4-MAX(12*(I$4-1),IF(RentRoll!$K$15="",99999,RentRoll!$K$15),RentRoll!$R$15)))/12 -> 0 | J18: =RentRoll!$H$15*RentRoll!$P$15*(1+RentRoll!$Q$15)^(J$4-1)*(MAX(0,MIN(12*J$4,IF(RentRoll!$K$15="",99999,RentRoll!$K$15))-MAX(12*(J$4-1),RentRoll!$R$15))+RentRoll!$L$15*MAX(0,12*J$4-MAX(12*(J$4-1),IF(RentRoll!$K$15="",99999,RentRoll!$K$15),RentRoll!$R$15)))/12 -> 0 | K18: =RentRoll!$H$15*RentRoll!$P$15*(1+RentRoll!$Q$15)^(K$4-1)*(MAX(0,MIN(12*K$4,IF(RentRoll!$K$15="",99999,RentRoll!$K$15))-MAX(12*(K$4-1),RentRoll!$R$15))+RentRoll!$L$15*MAX(0,12*K$4-MAX(12*(K$4-1),IF(RentRoll!$K$15="",99999,RentRoll!$K$15),RentRoll!$R$15)))/12 -> 0 | ... N18: =RentRoll!$H$15*RentRoll!$P$15*(1+RentRoll!$Q$15)^(N$4-1)*(MAX(0,MIN(12*N$4,IF(RentRoll!$K$15="",99999,RentRoll!$K$15))-MAX(12*(N$4-1),RentRoll!$R$15))+RentRoll!$L$15*MAX(0,12*N$4-MAX(12*(N$4-1),IF(RentRoll!$K$15="",99999,RentRoll!$K$15),RentRoll!$R$15)))/12 -> 0
A19: Total scenario revenue | D19: =SUM(D9:D18) -> 457700 | E19: =SUM(E9:E18) -> 485336 | F19: =SUM(F9:F18) -> 490984.52 | G19: =SUM(G9:G18) -> 505714.06 | H19: =SUM(H9:H18) -> 520885.48 | I19: =SUM(I9:I18) -> 509385.03 | J19: =SUM(J9:J18) -> 524666.58 | K19: =SUM(K9:K18) -> 540406.58 | ... N19: =SUM(N9:N18) -> 590516.86
A20: Less: vacancy & credit loss | D20: =-D19*Vacancy -> -22885 | E20: =-E19*Vacancy -> -24266.8 | F20: =-F19*Vacancy -> -24549.226 | G20: =-G19*Vacancy -> -25285.703 | H20: =-H19*Vacancy -> -26044.274 | I20: =-I19*Vacancy -> -25469.251 | J20: =-J19*Vacancy -> -26233.329 | K20: =-K19*Vacancy -> -27020.329 | ... N20: =-N19*Vacancy -> -29525.843
A21: Effective gross revenue | D21: =D19+D20 -> 434815 | E21: =E19+E20 -> 461069.2 | F21: =F19+F20 -> 466435.29 | G21: =G19+G20 -> 480428.35 | H21: =H19+H20 -> 494841.2 | I21: =I19+I20 -> 483915.78 | J21: =J19+J20 -> 498433.25 | K21: =K19+K20 -> 513386.25 | ... N21: =N19+N20 -> 560991.01
A23: OPERATING EXPENSES
A24: Property tax | D24: =-IF(TaxSwitch=1,PurchPrice*TaxRate,SellerTax)*(1+ExpGrowth)^(D$4-1) -> -5000 | E24: =-IF(TaxSwitch=1,PurchPrice*TaxRate,SellerTax)*(1+ExpGrowth)^(E$4-1) -> -5150 | F24: =-IF(TaxSwitch=1,PurchPrice*TaxRate,SellerTax)*(1+ExpGrowth)^(F$4-1) -> -5304.5 | G24: =-IF(TaxSwitch=1,PurchPrice*TaxRate,SellerTax)*(1+ExpGrowth)^(G$4-1) -> -5463.635 | H24: =-IF(TaxSwitch=1,PurchPrice*TaxRate,SellerTax)*(1+ExpGrowth)^(H$4-1) -> -5627.5441 | I24: =-IF(TaxSwitch=1,PurchPrice*TaxRate,SellerTax)*(1+ExpGrowth)^(I$4-1) -> -5796.3704 | J24: =-IF(TaxSwitch=1,PurchPrice*TaxRate,SellerTax)*(1+ExpGrowth)^(J$4-1) -> -5970.2615 | K24: =-IF(TaxSwitch=1,PurchPrice*TaxRate,SellerTax)*(1+ExpGrowth)^(K$4-1) -> -6149.3693 | ... N24: =-IF(TaxSwitch=1,PurchPrice*TaxRate,SellerTax)*(1+ExpGrowth)^(N$4-1) -> -6719.5819
A25: Liability insurance | D25: =-Insurance*(1+ExpGrowth)^(D$4-1) -> -2000 | E25: =-Insurance*(1+ExpGrowth)^(E$4-1) -> -2060 | F25: =-Insurance*(1+ExpGrowth)^(F$4-1) -> -2121.8 | G25: =-Insurance*(1+ExpGrowth)^(G$4-1) -> -2185.454 | H25: =-Insurance*(1+ExpGrowth)^(H$4-1) -> -2251.0176 | I25: =-Insurance*(1+ExpGrowth)^(I$4-1) -> -2318.5481 | J25: =-Insurance*(1+ExpGrowth)^(J$4-1) -> -2388.1046 | K25: =-Insurance*(1+ExpGrowth)^(K$4-1) -> -2459.7477 | ... N25: =-Insurance*(1+ExpGrowth)^(N$4-1) -> -2687.8328
A26: Other opex / repairs | D26: =-OtherOpex*(1+ExpGrowth)^(D$4-1) -> 0 | E26: =-OtherOpex*(1+ExpGrowth)^(E$4-1) -> 0 | F26: =-OtherOpex*(1+ExpGrowth)^(F$4-1) -> 0 | G26: =-OtherOpex*(1+ExpGrowth)^(G$4-1) -> 0 | H26: =-OtherOpex*(1+ExpGrowth)^(H$4-1) -> 0 | I26: =-OtherOpex*(1+ExpGrowth)^(I$4-1) -> 0 | J26: =-OtherOpex*(1+ExpGrowth)^(J$4-1) -> 0 | K26: =-OtherOpex*(1+ExpGrowth)^(K$4-1) -> 0 | ... N26: =-OtherOpex*(1+ExpGrowth)^(N$4-1) -> 0
A27: Management fee | D27: =-MgmtPct*D21 -> 0 | E27: =-MgmtPct*E21 -> 0 | F27: =-MgmtPct*F21 -> 0 | G27: =-MgmtPct*G21 -> 0 | H27: =-MgmtPct*H21 -> 0 | I27: =-MgmtPct*I21 -> 0 | J27: =-MgmtPct*J21 -> 0 | K27: =-MgmtPct*K21 -> 0 | ... N27: =-MgmtPct*N21 -> 0
A28: Total operating expenses | D28: =SUM(D24:D27) -> -7000 | E28: =SUM(E24:E27) -> -7210 | F28: =SUM(F24:F27) -> -7426.3 | G28: =SUM(G24:G27) -> -7649.089 | H28: =SUM(H24:H27) -> -7878.5617 | I28: =SUM(I24:I27) -> -8114.9185 | J28: =SUM(J24:J27) -> -8358.3661 | K28: =SUM(K24:K27) -> -8609.1171 | ... N28: =SUM(N24:N27) -> -9407.4147
A30: NET OPERATING INCOME (NOI) | D30: =D21+D28 -> 427815 | E30: =E21+E28 -> 453859.2 | F30: =F21+F28 -> 459008.99 | G30: =G21+G28 -> 472779.26 | H30: =H21+H28 -> 486962.64 | I30: =I21+I28 -> 475800.86 | J30: =J21+J28 -> 490074.88 | K30: =K21+K28 -> 504777.13 | ... N30: =N21+N28 -> 551583.6
A31: Memo: NOI before reassessed tax (price-solve helper) | D31: =D30+IF(TaxSwitch=1,PurchPrice*TaxRate*(1+ExpGrowth)^(D$4-1),0) -> 427815 | E31: =E30+IF(TaxSwitch=1,PurchPrice*TaxRate*(1+ExpGrowth)^(E$4-1),0) -> 453859.2 | F31: =F30+IF(TaxSwitch=1,PurchPrice*TaxRate*(1+ExpGrowth)^(F$4-1),0) -> 459008.99 | G31: =G30+IF(TaxSwitch=1,PurchPrice*TaxRate*(1+ExpGrowth)^(G$4-1),0) -> 472779.26 | H31: =H30+IF(TaxSwitch=1,PurchPrice*TaxRate*(1+ExpGrowth)^(H$4-1),0) -> 486962.64 | I31: =I30+IF(TaxSwitch=1,PurchPrice*TaxRate*(1+ExpGrowth)^(I$4-1),0) -> 475800.86 | J31: =J30+IF(TaxSwitch=1,PurchPrice*TaxRate*(1+ExpGrowth)^(J$4-1),0) -> 490074.88 | K31: =K30+IF(TaxSwitch=1,PurchPrice*TaxRate*(1+ExpGrowth)^(K$4-1),0) -> 504777.13 | ... N31: =N30+IF(TaxSwitch=1,PurchPrice*TaxRate*(1+ExpGrowth)^(N$4-1),0) -> 551583.6
A32: Memo: reassessed tax per $1 of price (helper) | D32: =TaxSwitch*TaxRate*(1+ExpGrowth)^(D$4-1) -> 0 | E32: =TaxSwitch*TaxRate*(1+ExpGrowth)^(E$4-1) -> 0 | F32: =TaxSwitch*TaxRate*(1+ExpGrowth)^(F$4-1) -> 0 | G32: =TaxSwitch*TaxRate*(1+ExpGrowth)^(G$4-1) -> 0 | H32: =TaxSwitch*TaxRate*(1+ExpGrowth)^(H$4-1) -> 0 | I32: =TaxSwitch*TaxRate*(1+ExpGrowth)^(I$4-1) -> 0 | J32: =TaxSwitch*TaxRate*(1+ExpGrowth)^(J$4-1) -> 0 | K32: =TaxSwitch*TaxRate*(1+ExpGrowth)^(K$4-1) -> 0 | ... N32: =TaxSwitch*TaxRate*(1+ExpGrowth)^(N$4-1) -> 0
A34: CAPITAL ITEMS
A35: Capex (Capex tab) | D35: =-SUMIF(Capex!$E$6:$E$9,D$4,Capex!$K$6:$K$9) -> -112500 | E35: =-SUMIF(Capex!$E$6:$E$9,E$4,Capex!$K$6:$K$9) -> -45000 | F35: =-SUMIF(Capex!$E$6:$E$9,F$4,Capex!$K$6:$K$9) -> 0 | G35: =-SUMIF(Capex!$E$6:$E$9,G$4,Capex!$K$6:$K$9) -> 0 | H35: =-SUMIF(Capex!$E$6:$E$9,H$4,Capex!$K$6:$K$9) -> 0 | I35: =-SUMIF(Capex!$E$6:$E$9,I$4,Capex!$K$6:$K$9) -> 0 | J35: =-SUMIF(Capex!$E$6:$E$9,J$4,Capex!$K$6:$K$9) -> 0 | K35: =-SUMIF(Capex!$E$6:$E$9,K$4,Capex!$K$6:$K$9) -> 0 | ... N35: =-SUMIF(Capex!$E$6:$E$9,N$4,Capex!$K$6:$K$9) -> 0
A36: Capital reserves | D36: =-ReservePerAcre*Acres*(1+ExpGrowth)^(D$4-1) -> 0 | E36: =-ReservePerAcre*Acres*(1+ExpGrowth)^(E$4-1) -> 0 | F36: =-ReservePerAcre*Acres*(1+ExpGrowth)^(F$4-1) -> 0 | G36: =-ReservePerAcre*Acres*(1+ExpGrowth)^(G$4-1) -> 0 | H36: =-ReservePerAcre*Acres*(1+ExpGrowth)^(H$4-1) -> 0 | I36: =-ReservePerAcre*Acres*(1+ExpGrowth)^(I$4-1) -> 0 | J36: =-ReservePerAcre*Acres*(1+ExpGrowth)^(J$4-1) -> 0 | K36: =-ReservePerAcre*Acres*(1+ExpGrowth)^(K$4-1) -> 0 | ... N36: =-ReservePerAcre*Acres*(1+ExpGrowth)^(N$4-1) -> 0
A38: UNLEVERED CASH FLOW
A39: Purchase price + closing costs | C39: =-PurchPrice*(1+CloseCost) -> -5582500
A40: NOI (in hold) | D40: =D30*D$5 -> 427815 | E40: =E30*E$5 -> 453859.2 | F40: =F30*F$5 -> 459008.99 | G40: =G30*G$5 -> 472779.26 | H40: =H30*H$5 -> 486962.64 | I40: =I30*I$5 -> 475800.86 | J40: =J30*J$5 -> 490074.88 | K40: =K30*K$5 -> 0 | ... N40: =N30*N$5 -> 0
A41: Capex & reserves (in hold) | D41: =(D35+D36)*D$5 -> -112500 | E41: =(E35+E36)*E$5 -> -45000 | F41: =(F35+F36)*F$5 -> 0 | G41: =(G35+G36)*G$5 -> 0 | H41: =(H35+H36)*H$5 -> 0 | I41: =(I35+I36)*I$5 -> 0 | J41: =(J35+J36)*J$5 -> 0 | K41: =(K35+K36)*K$5 -> 0 | ... N41: =(N35+N36)*N$5 -> 0
A42: Forward NOI (next year) for exit | D42: =E30 -> 453859.2 | E42: =F30 -> 459008.99 | F42: =G30 -> 472779.26 | G42: =H30 -> 486962.64 | H42: =I30 -> 475800.86 | I42: =J30 -> 490074.88 | J42: =K30 -> 504777.13 | K42: =L30 -> 519920.44 | ... N42: =O30 -> 0
A43: Gross exit value | D43: =D$6*D42/ExitCap -> 0 | E43: =E$6*E42/ExitCap -> 0 | F43: =F$6*F42/ExitCap -> 0 | G43: =G$6*G42/ExitCap -> 0 | H43: =H$6*H42/ExitCap -> 0 | I43: =I$6*I42/ExitCap -> 0 | J43: =J$6*J42/ExitCap -> 7211101.9 | K43: =K$6*K42/ExitCap -> 0 | ... N43: =N$6*N42/ExitCap -> 0
A44: Less: sale costs | D44: =-D43*SaleCost -> 0 | E44: =-E43*SaleCost -> 0 | F44: =-F43*SaleCost -> 0 | G44: =-G43*SaleCost -> 0 | H44: =-H43*SaleCost -> 0 | I44: =-I43*SaleCost -> 0 | J44: =-J43*SaleCost -> -144222.04 | K44: =-K43*SaleCost -> 0 | ... N44: =-N43*SaleCost -> 0
A45: Net sale proceeds | D45: =D43+D44 -> 0 | E45: =E43+E44 -> 0 | F45: =F43+F44 -> 0 | G45: =G43+G44 -> 0 | H45: =H43+H44 -> 0 | I45: =I43+I44 -> 0 | J45: =J43+J44 -> 7066879.8 | K45: =K43+K44 -> 0 | ... N45: =N43+N44 -> 0
A46: UNLEVERED NET CASH FLOW | C46: =C39 -> -5582500 | D46: =D40+D41+D45 -> 315315 | E46: =E40+E41+E45 -> 408859.2 | F46: =F40+F41+F45 -> 459008.99 | G46: =G40+G41+G45 -> 472779.26 | H46: =H40+H41+H45 -> 486962.64 | I46: =I40+I41+I45 -> 475800.86 | J46: =J40+J41+J45 -> 7556954.7 | K46: =K40+K41+K45 -> 0 | ... N46: =N40+N41+N45 -> 0
...

Sheet Sens
A1: Sensitivity Engine
A2: Rent-growth shift applies to tenants with no stated bump. Every cell recomputes with the full model; no data tables or macros.
A4: Year | C4: =CashFlow!C4 -> 0 | D4: =CashFlow!D4 -> 1 | E4: =CashFlow!E4 -> 2 | F4: =CashFlow!F4 -> 3 | G4: =CashFlow!G4 -> 4 | H4: =CashFlow!H4 -> 5 | I4: =CashFlow!I4 -> 6 | J4: =CashFlow!J4 -> 7 | ... N4: =CashFlow!N4 -> 11
A6: Block 1: rent-growth shift | B6: =(0-2)*StepG -> -0.02
A7: =RentRoll!B6 -> S&A Leasing | D7: =RentRoll!$H$6*RentRoll!$P$6*(1+IF(RentRoll!$I$6="",RentGrowth+$B$6,RentRoll!$I$6))^(D$4-1)*(MAX(0,MIN(12*D$4,IF(RentRoll!$K$6="",99999,RentRoll!$K$6))-MAX(12*(D$4-1),RentRoll!$R$6))+RentRoll!$L$6*MAX(0,12*D$4-MAX(12*(D$4-1),IF(RentRoll!$K$6="",99999,RentRoll!$K$6),RentRoll!$R$6)))/12 -> 156000 | E7: =RentRoll!$H$6*RentRoll!$P$6*(1+IF(RentRoll!$I$6="",RentGrowth+$B$6,RentRoll!$I$6))^(E$4-1)*(MAX(0,MIN(12*E$4,IF(RentRoll!$K$6="",99999,RentRoll!$K$6))-MAX(12*(E$4-1),RentRoll!$R$6))+RentRoll!$L$6*MAX(0,12*E$4-MAX(12*(E$4-1),IF(RentRoll!$K$6="",99999,RentRoll!$K$6),RentRoll!$R$6)))/12 -> 160680 | F7: =RentRoll!$H$6*RentRoll!$P$6*(1+IF(RentRoll!$I$6="",RentGrowth+$B$6,RentRoll!$I$6))^(F$4-1)*(MAX(0,MIN(12*F$4,IF(RentRoll!$K$6="",99999,RentRoll!$K$6))-MAX(12*(F$4-1),RentRoll!$R$6))+RentRoll!$L$6*MAX(0,12*F$4-MAX(12*(F$4-1),IF(RentRoll!$K$6="",99999,RentRoll!$K$6),RentRoll!$R$6)))/12 -> 165500.4 | G7: =RentRoll!$H$6*RentRoll!$P$6*(1+IF(RentRoll!$I$6="",RentGrowth+$B$6,RentRoll!$I$6))^(G$4-1)*(MAX(0,MIN(12*G$4,IF(RentRoll!$K$6="",99999,RentRoll!$K$6))-MAX(12*(G$4-1),RentRoll!$R$6))+RentRoll!$L$6*MAX(0,12*G$4-MAX(12*(G$4-1),IF(RentRoll!$K$6="",99999,RentRoll!$K$6),RentRoll!$R$6)))/12 -> 170465.41 | H7: =RentRoll!$H$6*RentRoll!$P$6*(1+IF(RentRoll!$I$6="",RentGrowth+$B$6,RentRoll!$I$6))^(H$4-1)*(MAX(0,MIN(12*H$4,IF(RentRoll!$K$6="",99999,RentRoll!$K$6))-MAX(12*(H$4-1),RentRoll!$R$6))+RentRoll!$L$6*MAX(0,12*H$4-MAX(12*(H$4-1),IF(RentRoll!$K$6="",99999,RentRoll!$K$6),RentRoll!$R$6)))/12 -> 175579.37 | I7: =RentRoll!$H$6*RentRoll!$P$6*(1+IF(RentRoll!$I$6="",RentGrowth+$B$6,RentRoll!$I$6))^(I$4-1)*(MAX(0,MIN(12*I$4,IF(RentRoll!$K$6="",99999,RentRoll!$K$6))-MAX(12*(I$4-1),RentRoll!$R$6))+RentRoll!$L$6*MAX(0,12*I$4-MAX(12*(I$4-1),IF(RentRoll!$K$6="",99999,RentRoll!$K$6),RentRoll!$R$6)))/12 -> 153719.74 | J7: =RentRoll!$H$6*RentRoll!$P$6*(1+IF(RentRoll!$I$6="",RentGrowth+$B$6,RentRoll!$I$6))^(J$4-1)*(MAX(0,MIN(12*J$4,IF(RentRoll!$K$6="",99999,RentRoll!$K$6))-MAX(12*(J$4-1),RentRoll!$R$6))+RentRoll!$L$6*MAX(0,12*J$4-MAX(12*(J$4-1),IF(RentRoll!$K$6="",99999,RentRoll!$K$6),RentRoll!$R$6)))/12 -> 158331.33 | K7: =RentRoll!$H$6*RentRoll!$P$6*(1+IF(RentRoll!$I$6="",RentGrowth+$B$6,RentRoll!$I$6))^(K$4-1)*(MAX(0,MIN(12*K$4,IF(RentRoll!$K$6="",99999,RentRoll!$K$6))-MAX(12*(K$4-1),RentRoll!$R$6))+RentRoll!$L$6*MAX(0,12*K$4-MAX(12*(K$4-1),IF(RentRoll!$K$6="",99999,RentRoll!$K$6),RentRoll!$R$6)))/12 -> 163081.27 | ... N7: =RentRoll!$H$6*RentRoll!$P$6*(1+IF(RentRoll!$I$6="",RentGrowth+$B$6,RentRoll!$I$6))^(N$4-1)*(MAX(0,MIN(12*N$4,IF(RentRoll!$K$6="",99999,RentRoll!$K$6))-MAX(12*(N$4-1),RentRoll!$R$6))+RentRoll!$L$6*MAX(0,12*N$4-MAX(12*(N$4-1),IF(RentRoll!$K$6="",99999,RentRoll!$K$6),RentRoll!$R$6)))/12 -> 178203.31
